1640227487.508752｜[DEBUG] [__main__] Starting up...
1640227765.505318｜[DEBUG] [__main__] Starting up...
1640227905.135265｜[DEBUG] [__main__] Starting up...
1640227963.561103｜[DEBUG] [__main__] Starting up...
1640228012.590535｜[DEBUG] [__main__] Starting up...
1640228015.220192｜[INFO] [takt.on_ready] Saiki is ready
1640228027.208391｜[DEBUG] [__main__] Starting up...
1640228029.826157｜[INFO] [takt.on_ready] Takt is ready
1640228144.388709｜[DEBUG] [__main__] Starting up...
1640228147.000168｜[INFO] [takt.on_ready] Takt is ready
1640228184.096864｜[DEBUG] [__main__] Starting up...
1640228186.75232｜[INFO] [takt.on_ready] Takt is ready
1640228191.488019｜[ERROR] [error.error_handler] An unknown error occured: AttributeError 'NoneType' object has no attribute 'stop'
1640228377.625428｜[DEBUG] [__main__] Starting up...
1640228380.262292｜[INFO] [takt.on_ready] Takt is ready
1640228384.131218｜[ERROR] [error.error_handler] An unknown error occured: RuntimeError PyNaCl library needed in order to use voice
1640228559.043179｜[DEBUG] [__main__] Starting up...
1640228561.684944｜[INFO] [takt.on_ready] Takt is ready
1640228576.080789｜[ERROR] [error.error_handler] An unknown error occured: TypeError expected str, bytes or os.PathLike object, not dict
1640228624.21999｜[DEBUG] [__main__] Starting up...
1640228626.832654｜[INFO] [takt.on_ready] Takt is ready
1640228636.693718｜[ERROR] [error.error_handler] An unknown error occured: TypeError string indices must be integers
1640228659.14154｜[DEBUG] [__main__] Starting up...
1640228661.727052｜[INFO] [takt.on_ready] Takt is ready
1640282061.439649｜[DEBUG] [__main__] Starting up...
1640282089.306488｜[DEBUG] [__main__] Starting up...
1640282091.954405｜[INFO] [takt.on_ready] Takt is ready
1640284396.500339｜[DEBUG] [__main__] Starting up...
1640284397.73787｜[INFO] [bot.on_connect] Takt is connected to Discord (latency: 104.47 ms)
1640284399.747251｜[INFO] [bot.on_ready] Takt is ready
1640284628.922011｜[DEBUG] [__main__] Starting up...
1640284629.711909｜[INFO] [bot.on_connect] Takt is connected to Discord (latency: 102.41 ms)
1640284631.719986｜[INFO] [bot.on_ready] Takt is ready
1640284648.011249｜[ERROR] [nasse.exceptions.base.NotInVoiceChannel.__init__] An unexpected error occured on the server
1640284659.813195｜[DEBUG] [__main__] Starting up...
1640284660.551017｜[INFO] [bot.on_connect] Takt is connected to Discord (latency: 116.23 ms)
1640284662.558197｜[INFO] [bot.on_ready] Takt is ready
1640284664.685826｜[ERROR] [nasse.exceptions.base.NotInVoiceChannel.__init__] An unexpected error occured on the server
1640284664.69026｜[ERROR] [error.error_handler] An unknown error occured: CommandInvokeError Command raised an exception: NotInVoiceChannel: An unexpected error occured on the server
1640284721.776744｜[DEBUG] [__main__] Starting up...
1640284722.423206｜[INFO] [bot.on_connect] Takt is connected to Discord (latency: 101.5 ms)
1640284724.432744｜[INFO] [bot.on_ready] Takt is ready
1640284728.13907｜[ERROR] [nasse.exceptions.base.NotInVoiceChannel.__init__] An unexpected error occured on the server
1640284728.143277｜[ERROR] [error.error_handler] An unknown error occured: CommandInvokeError Command raised an exception: NotInVoiceChannel: An unexpected error occured on the server
1640284774.603765｜[DEBUG] [__main__] Starting up...
1640284775.253275｜[INFO] [bot.on_connect] Takt is connected to Discord (latency: 106.4 ms)
1640284777.257334｜[INFO] [bot.on_ready] Takt is ready
1640284779.467927｜[ERROR] [nasse.exceptions.base.NotInVoiceChannel.__init__] An unexpected error occured on the server
1640284779.472523｜[ERROR] [error.error_handler] An unknown error occured: CommandInvokeError Command raised an exception: NotInVoiceChannel: An unexpected error occured on the server
1640284944.424128｜[DEBUG] [__main__] Starting up...
1640284945.030846｜[INFO] [bot.on_connect] Takt is connected to Discord (latency: 102.08 ms)
1640284947.039357｜[INFO] [bot.on_ready] Takt is ready
1640284950.011385｜[ERROR] [nasse.exceptions.base.NotInVoiceChannel.__init__] An unexpected error occured on the server
1640284996.81218｜[DEBUG] [__main__] Starting up...
1640284997.438886｜[INFO] [bot.on_connect] Takt is connected to Discord (latency: 122.44 ms)
1640284999.518166｜[INFO] [bot.on_ready] Takt is ready
1640285004.629698｜[DEBUG] [__main__] Starting up...
1640285005.301161｜[INFO] [bot.on_connect] Takt is connected to Discord (latency: 125.61 ms)
1640285007.312114｜[INFO] [bot.on_ready] Takt is ready
1640285013.224252｜[ERROR] [nasse.exceptions.base.NotInVoiceChannel.__init__] {mention} ❌ You do not seem to be in a voice channel
1640285131.100006｜[ERROR] [error.error_handler] An unknown error occured: IndexError list index out of range
1640285340.223929｜[DEBUG] [__main__] Starting up...
1640285341.065607｜[INFO] [bot.on_connect] Takt is connected to Discord (latency: 115.15 ms)
1640285343.070615｜[INFO] [bot.on_ready] Takt is ready
1640286833.000554｜[DEBUG] [__main__] Starting up...
1640286833.636215｜[INFO] [bot.on_connect] Takt is connected to Discord (latency: 102.42 ms)
1640286835.643692｜[INFO] [bot.on_ready] Takt is ready
1640879807.422661｜[DEBUG] [bot] Defining client and slash client
1640879807.464569｜[DEBUG] [bot] The defined prefix is '+' (or mention)
